Workbook

Sheet Overview
A1: 365-Day AI Engineer Roadmap - 2 hours/day edition
A2: Day 1 = 07 Sep 2026 (Mon). Every day = 2 h: LEARN 45 min (read/watch the exact section listed) + IMPLEMENT/BUILD 75 min (code it) + 5 min revise. Day 7 = weekly checkpoint (grey, 2 h). Yellow = project checkpoint weeks. DSA is NOT in this plan - it uses its own time. Rule: if a day overruns, carry it to the next day and drop that week's lowest-value item; never skip the checkpoint.
A4: Week | B4: Days | C4: Phase | D4: Theme | E4: Difficulty | F4: Checkpoint | G4: Days done | H4: % done
A5: 1 | B5: 1-7 | C5: Phase 0 - Assessment & setup | D5: Assessment + engineering setup | E5: 2 | F5: CP0 | G5: =COUNTIF('365-Day Plan (2h)'!O2:O8,"Y") -> 0 | H5: =G5/7 -> 0
A6: 2 | B6: 8-14 | C6: Phase 1 - Mathematics | D6: Linear algebra I | E6: 3 | G6: =COUNTIF('365-Day Plan (2h)'!O9:O15,"Y") -> 0 | H6: =G6/7 -> 0
A7: 3 | B7: 15-21 | C7: Phase 1 - Mathematics | D7: Linear algebra II | E7: 4 | G7: =COUNTIF('365-Day Plan (2h)'!O16:O22,"Y") -> 0 | H7: =G7/7 -> 0
A8: 4 | B8: 22-28 | C8: Phase 1 - Mathematics | D8: Calculus & optimisation | E8: 4 | G8: =COUNTIF('365-Day Plan (2h)'!O23:O29,"Y") -> 0 | H8: =G8/7 -> 0
A9: 5 | B9: 29-35 | C9: Phase 1 - Mathematics | D9: Probability | E9: 3 | G9: =COUNTIF('365-Day Plan (2h)'!O30:O36,"Y") -> 0 | H9: =G9/7 -> 0
A10: 6 | B10: 36-42 | C10: Phase 1 - Mathematics | D10: Statistics | E10: 3 | F10: Math diagnostic v2 | G10: =COUNTIF('365-Day Plan (2h)'!O37:O43,"Y") -> 0 | H10: =G10/7 -> 0
A11: 7 | B11: 43-49 | C11: Phase 2 - Classical & advanced ML | D11: Regression, classification, metrics | E11: 3 | G11: =COUNTIF('365-Day Plan (2h)'!O44:O50,"Y") -> 0 | H11: =G11/7 -> 0
A12: 8 | B12: 50-56 | C12: Phase 2 - Classical & advanced ML | D12: Trees, forests, boosting | E12: 3 | G12: =COUNTIF('365-Day Plan (2h)'!O51:O57,"Y") -> 0 | H12: =G12/7 -> 0
A13: 9 | B13: 57-63 | C13: Phase 2 - Classical & advanced ML | D13: Unsupervised & anomaly | E13: 3 | G13: =COUNTIF('365-Day Plan (2h)'!O58:O64,"Y") -> 0 | H13: =G13/7 -> 0
A14: 10 | B14: 64-70 | C14: Phase 2 - Classical & advanced ML | D14: Advanced ML | E14: 4 | G14: =COUNTIF('365-Day Plan (2h)'!O65:O71,"Y") -> 0 | H14: =G14/7 -> 0
A15: 11 | B15: 71-77 | C15: Phase 2 - Classical & advanced ML | D15: PROJECT 1: PredictiveMaint-ML (week 1) | E15: 4 | G15: =COUNTIF('365-Day Plan (2h)'!O72:O78,"Y") -> 0 | H15: =G15/7 -> 0
A16: 12 | B16: 78-84 | C16: Phase 2 - Classical & advanced ML | D16: PROJECT 1 (week 2) | E16: 4 | F16: CP1 | G16: =COUNTIF('365-Day Plan (2h)'!O79:O85,"Y") -> 0 | H16: =G16/7 -> 0
A17: 13 | B17: 85-91 | C17: Phase 3 - Deep learning & PyTorch | D17: DL from scratch | E17: 4 | G17: =COUNTIF('365-Day Plan (2h)'!O86:O92,"Y") -> 0 | H17: =G17/7 -> 0
A18: 14 | B18: 92-98 | C18: Phase 3 - Deep learning & PyTorch | D18: PyTorch mastery | E18: 3 | G18: =COUNTIF('365-Day Plan (2h)'!O93:O99,"Y") -> 0 | H18: =G18/7 -> 0
A19: 15 | B19: 99-105 | C19: Phase 3 - Deep learning & PyTorch | D19: Training craft | E19: 4 | G19: =COUNTIF('365-Day Plan (2h)'!O100:O106,"Y") -> 0 | H19: =G19/7 -> 0
A20: 16 | B20: 106-112 | C20: Phase 3 - Deep learning & PyTorch | D20: CNNs | E20: 3 | G20: =COUNTIF('365-Day Plan (2h)'!O107:O113,"Y") -> 0 | H20: =G20/7 -> 0
A21: 17 | B21: 113-119 | C21: Phase 3 - Deep learning & PyTorch | D21: Sequence models | E21: 3 | G21: =COUNTIF('365-Day Plan (2h)'!O114:O120,"Y") -> 0 | H21: =G21/7 -> 0
A22: 18 | B22: 120-126 | C22: Phase 3 - Deep learning & PyTorch | D22: PROJECT 2: EdgeVibe-CNN (week 1) | E22: 4 | G22: =COUNTIF('365-Day Plan (2h)'!O121:O127,"Y") -> 0 | H22: =G22/7 -> 0
A23: 19 | B23: 127-133 | C23: Phase 3 - Deep learning & PyTorch | D23: PROJECT 2 (week 2) | E23: 4 | F23: CP2 | G23: =COUNTIF('365-Day Plan (2h)'!O128:O134,"Y") -> 0 | H23: =G23/7 -> 0
A24: 20 | B24: 134-140 | C24: Phase 4 - Transformers & LLMs | D24: Attention & transformer | E24: 4 | G24: =COUNTIF('365-Day Plan (2h)'!O135:O141,"Y") -> 0 | H24: =G24/7 -> 0
A25: 21 | B25: 141-147 | C25: Phase 4 - Transformers & LLMs | D25: Building GPT | E25: 4 | G25: =COUNTIF('365-Day Plan (2h)'!O142:O148,"Y") -> 0 | H25: =G25/7 -> 0
A26: 22 | B26: 148-154 | C26: Phase 4 - Transformers & LLMs | D26: Pretraining & inference | E26: 4 | G26: =COUNTIF('365-Day Plan (2h)'!O149:O155,"Y") -> 0 | H26: =G26/7 -> 0
A27: 23 | B27: 155-161 | C27: Phase 4 - Transformers & LLMs | D27: LLM systems | E27: 4 | G27: =COUNTIF('365-Day Plan (2h)'!O156:O162,"Y") -> 0 | H27: =G27/7 -> 0
A28: 24 | B28: 162-168 | C28: Phase 4 - Transformers & LLMs | D28: LLM behaviour & structured output | E28: 3 | G28: =COUNTIF('365-Day Plan (2h)'!O163:O169,"Y") -> 0 | H28: =G28/7 -> 0
A29: 25 | B29: 169-175 | C29: Phase 4 - Transformers & LLMs | D29: PROJECT 3: MiniGPT-Domain (week 1) | E29: 5 | G29: =COUNTIF('365-Day Plan (2h)'!O170:O176,"Y") -> 0 | H29: =G29/7 -> 0
A30: 26 | B30: 176-182 | C30: Phase 4 - Transformers & LLMs | D30: PROJECT 3 (week 2) | E30: 5 | F30: CP3 | G30: =COUNTIF('365-Day Plan (2h)'!O177:O183,"Y") -> 0 | H30: =G30/7 -> 0
A31: 27 | B31: 183-189 | C31: Phase 5 - Embeddings & RAG | D31: Embeddings & vector search | E31: 3 | G31: =COUNTIF('365-Day Plan (2h)'!O184:O190,"Y") -> 0 | H31: =G31/7 -> 0
A32: 28 | B32: 190-196 | C32: Phase 5 - Embeddings & RAG | D32: RAG Level 1-2 | E32: 3 | G32: =COUNTIF('365-Day Plan (2h)'!O191:O197,"Y") -> 0 | H32: =G32/7 -> 0
A33: 29 | B33: 197-203 | C33: Phase 5 - Embeddings & RAG | D33: RAG Level 3 | E33: 4 | G33: =COUNTIF('365-Day Plan (2h)'!O198:O204,"Y") -> 0 | H33: =G33/7 -> 0
A34: 30 | B34: 204-210 | C34: Phase 5 - Embeddings & RAG | D34: RAG Level 4: evaluation, cost, cache | E34: 4 | G34: =COUNTIF('365-Day Plan (2h)'!O205:O211,"Y") -> 0 | H34: =G34/7 -> 0
A35: 31 | B35: 211-217 | C35: Phase 5 - Embeddings & RAG | D35: PROJECT 4: RegRAG (week 1) | E35: 5 | G35: =COUNTIF('365-Day Plan (2h)'!O212:O218,"Y") -> 0 | H35: =G35/7 -> 0
A36: 32 | B36: 218-224 | C36: Phase 5 - Embeddings & RAG | D36: PROJECT 4 (week 2) | E36: 5 | F36: CP4 | G36: =COUNTIF('365-Day Plan (2h)'!O219:O225,"Y") -> 0 | H36: =G36/7 -> 0
A37: 33 | B37: 225-231 | C37: Phase 6 - Fine-tuning | D37: PEFT & quantisation | E37: 4 | G37: =COUNTIF('365-Day Plan (2h)'!O226:O232,"Y") -> 0 | H37: =G37/7 -> 0
A38: 34 | B38: 232-238 | C38: Phase 6 - Fine-tuning | D38: Instruction tuning, DPO, RAG-vs-FT | E38: 4 | G38: =COUNTIF('365-Day Plan (2h)'!O233:O239,"Y") -> 0 | H38: =G38/7 -> 0
A39: 35 | B39: 239-245 | C39: Phase 6 - Fine-tuning | D39: Whisper fine-tune on Tanglish | E39: 4 | G39: =COUNTIF('365-Day Plan (2h)'!O240:O246,"Y") -> 0 | H39: =G39/7 -> 0
A40: 36 | B40: 246-252 | C40: Phase 7 - Agents | D40: Agents I: loop & tools | E40: 3 | G40: =COUNTIF('365-Day Plan (2h)'!O247:O253,"Y") -> 0 | H40: =G40/7 -> 0
A41: 37 | B41: 253-259 | C41: Phase 7 - Agents | D41: Agents II: workflows vs agents | E41: 4 | G41: =COUNTIF('365-Day Plan (2h)'!O254:O260,"Y") -> 0 | H41: =G41/7 -> 0
...

Sheet 365-Day Plan (2h)
A1: Day | B1: Date | C1: Week | D1: Phase | E1: Topic | F1: Concepts | G1: LEARN (45 min) - source & section | H1: Source key | I1: Source URL | J1: IMPLEMENT / BUILD (75 min) | K1: Revise (5 min) | L1: Deliverable | M1: Difficulty | N1: Checkpoint | O1: Done (Y/N)
A2: 1 | B2: 46272 | C2: 1 | D2: Phase 0 - Assessment & setup | E2: Environment + repo | F2: uv, pyproject, pytest, pre-commit, pyright | G2: PYDOCS: pytest fixtures; PROGIT ch 2 | H2: PYDOCS | I2: https://docs.python.org/3/library/asyncio.html | J2: Create `ai-lab` repo skeleton; one typed module + test; CI | K2: Yesterday: - | L2: Repo + CI green | M2: 2
A3: 2 | B3: 46273 | C3: 1 | D3: Phase 0 - Assessment & setup | E3: Math diagnostic | F3: LA/calc/prob/opt baseline | G3: None - closed-book test | H3: MML | I3: https://mml-book.github.io/ | J3: Take 20-Q diagnostic (MML chapter exercises); grade; weak list | K3: Yesterday: Environment + repo | L3: Score + weak topics | M3: 2
A4: 3 | B4: 46274 | C4: 1 | D4: Phase 0 - Assessment & setup | E4: PyTorch diagnostic | F4: Training loop, backprop | G4: None | H4: PT-TUT | I4: https://docs.pytorch.org/tutorials/ | J4: Blank-file MNIST training loop; derive 2-layer backprop on paper | K4: Yesterday: Math diagnostic | L4: Loop + derivation photo | M4: 2
A5: 4 | B5: 46275 | C5: 1 | D5: Phase 0 - Assessment & setup | E5: LLM/RAG diagnostic | F5: Attention, recall@k | G5: None | H5: OWN | I5: - | J5: Attention from memory; recall@5 on a past RAG corpus | K5: Yesterday: PyTorch diagnostic | L5: Two scripts + gap list | M5: 2
A6: 5 | B6: 46276 | C6: 1 | D6: Phase 0 - Assessment & setup | E6: Speech/agent/vector diagnostic | F6: WER, tool schemas, ANN | G6: JIWER README | H6: JIWER | I6: https://github.com/jitsi/jiwer | J6: WER on Tanglish clips; hackathon agent as plain loop; memory-engine vs FAISS | K6: Yesterday: LLM/RAG diagnostic | L6: WER table + benchmark | M6: 2
A7: 6 | B7: 46277 | C7: 1 | D7: Phase 0 - Assessment & setup | E7: Async + Docker + Git drills | F7: asyncio, retries, Dockerfile, rebase/bisect | G7: PYDOCS asyncio basics; DOCKER best practices | H7: PYDOCS | I7: https://docs.python.org/3/library/asyncio.html | J7: Async batch caller with rate limit; Dockerfile; rebase drill | K7: Yesterday: Speech/agent/vector diagnostic | L7: Container runs; CP0 self-grade | M7: 2
A8: 7 | B8: 46278 | C8: 1 | D8: Phase 0 - Assessment & setup | E8: WEEKLY CHECKPOINT 1: Assessment + engineering setup | F8: Whole week | G8: Anki + notes (30 min) | H8: OWN | I8: - | J8: Self-test 10 concept Qs + interview Qs: GIL vs asyncio for LLM calls; Why GPU runs aren't deterministic; What a Docker layer cache does (score bands: <40 weak, 40-60 needs work, 60-75 acceptable, 75-90 strong, 90+ excellent; <75% => revise before next week) (60 min); redo hardest implementation from blank file (30 min) | K8: Whole week | L8: Score + 200-word weekly note + push | M8: 2 | N8: CP0
A9: 8 | B9: 46279 | C9: 2 | D9: Phase 1 - Mathematics | E9: Vectors, span, systems | F9: Linear combinations, REF, Gaussian elimination | G9: MML 2.1-2.3; 3B1B-LA ep 1-3 | H9: MML | I9: https://mml-book.github.io/ | J9: Gaussian elimination from scratch; compare np.linalg.solve | K9: Yesterday: Async + Docker + Git drills | L9: `mathlib/linalg.py` + tests | M9: 3
A10: 9 | B10: 46280 | C10: 2 | D10: Phase 1 - Mathematics | E10: Vector spaces & independence | F10: Subspaces, independence test | G10: MML 2.4-2.5 | H10: MML | I10: https://mml-book.github.io/ | J10: Independence check via REF; 8 exercises | K10: Yesterday: Vectors, span, systems | L10: Commit | M10: 3
A11: 10 | B11: 46281 | C11: 2 | D11: Phase 1 - Mathematics | E11: Basis, rank, nullspace | F11: Rank-nullity, nullspace basis | G11: MML 2.6; 3B1B-LA ep 4-5 | H11: MML | I11: https://mml-book.github.io/ | J11: rank(), nullspace() | K11: Yesterday: Vector spaces & independence | L11: Commit + tests | M11: 3
A12: 11 | B12: 46282 | C12: 2 | D12: Phase 1 - Mathematics | E12: Linear mappings | F12: Matrix as map, image/kernel, composition | G12: MML 2.7; 3B1B-LA ep 6-8 | H12: MML | I12: https://mml-book.github.io/ | J12: Grid-transform visualiser | K12: Yesterday: Basis, rank, nullspace | L12: Plot + commit | M12: 3
A13: 12 | B13: 46283 | C13: 2 | D13: Phase 1 - Mathematics | E13: Change of basis, affine | F13: Basis change, affine maps | G13: MML 2.7.2-2.8; 3B1B-LA ep 12-13 | H13: MML | I13: https://mml-book.github.io/ | J13: Change-of-basis for rotation | K13: Yesterday: Linear mappings | L13: Commit | M13: 3
A14: 13 | B14: 46284 | C14: 2 | D14: Phase 1 - Mathematics | E14: Norms & inner products | F14: Lp norms, inner products, Cauchy-Schwarz | G14: MML 3.1-3.3 | H14: MML | I14: https://mml-book.github.io/ | J14: Norms; unit-ball plot; prove C-S once | K14: Yesterday: Change of basis, affine | L14: Commit + Anki 30 cards | M14: 3
A15: 14 | B15: 46285 | C15: 2 | D15: Phase 1 - Mathematics | E15: WEEKLY CHECKPOINT 2: Linear algebra I | F15: Whole week | G15: Anki + notes (30 min) | H15: OWN | I15: - | J15: Self-test 10 concept Qs + interview Qs: What rank tells you; When Ax=b has no/one/many solutions; Why matmul is composition (score bands: <40 weak, 40-60 needs work, 60-75 acceptable, 75-90 strong, 90+ excellent; <75% => revise before next week) (60 min); redo hardest implementation from blank file (30 min) | K15: Whole week | L15: Score + 200-word weekly note + push | M15: 3
A16: 15 | B16: 46286 | C16: 3 | D16: Phase 1 - Mathematics | E16: Angles, orthogonality, Gram-Schmidt | F16: Cosine similarity, orthonormal basis | G16: MML 3.4-3.5, 3.8; 3B1B-LA ep 9 | H16: MML | I16: https://mml-book.github.io/ | J16: cosine_similarity; Gram-Schmidt | K16: Yesterday: Norms & inner products | L16: Commit + tests | M16: 4
A17: 16 | B17: 46287 | C17: 3 | D17: Phase 1 - Mathematics | E17: Projections & least squares | F17: Projection matrix; least squares as projection | G17: MML 3.8 | H17: MML | I17: https://mml-book.github.io/ | J17: Least squares via projection vs lstsq; derive normal equations | K17: Yesterday: Angles, orthogonality, Gram-Schmidt | L17: Derivation + commit | M17: 4
A18: 17 | B18: 46288 | C18: 3 | D18: Phase 1 - Mathematics | E18: Determinant & eigen | F18: Volume scaling; characteristic polynomial; eigenspaces | G18: MML 4.1-4.2; 3B1B-LA ep 6, 14 | H18: MML | I18: https://mml-book.github.io/ | J18: det via elimination; power iteration; 2x2 by hand | K18: Yesterday: Projections & least squares | L18: Commit | M18: 4
A19: 18 | B19: 46289 | C19: 3 | D19: Phase 1 - Mathematics | E19: Eigendecomposition & Cholesky | F19: Spectral theorem; SPD | G19: MML 4.3-4.4 | H19: MML | I19: https://mml-book.github.io/ | J19: Symmetric eigendecomp; reconstruct A | K19: Yesterday: Determinant & eigen | L19: Commit + tests | M19: 4
A20: 19 | B20: 46290 | C20: 3 | D20: Phase 1 - Mathematics | E20: SVD | F20: U Sigma V^T; relation to A^T A; low rank | G20: MML 4.5-4.6 | H20: MML | I20: https://mml-book.github.io/ | J20: SVD via eigen(A^T A); image compression | K20: Yesterday: Eigendecomposition & Cholesky | L20: Plot + commit | M20: 4
... A42: 41 | B42: 46312 | C42: 6 | D42: Phase 1 - Mathematics | E42: Math diagnostic v2 | F42: All Phase 1 | G42: Anki review | H42: OWN | I42: - | J42: Retake 20-Q diagnostic; fix weak items | K42: Yesterday: A/B tests & drift tests | L42: Score >=75%; mathlib v1.0 | M42: 3
A43: 42 | B43: 46313 | C43: 6 | D43: Phase 1 - Mathematics | E43: WEEKLY CHECKPOINT 6: Statistics | F43: Whole week | G43: Anki + notes (30 min) | H43: OWN | I43: - | J43: Self-test 10 concept Qs + interview Qs: Bootstrap vs normal CI; What PSI measures; Compare two RAG configs statistically (score bands: <40 weak, 40-60 needs work, 60-75 acceptable, 75-90 strong, 90+ excellent; <75% => revise before next week) (60 min); redo hardest implementation from blank file (30 min) | K43: Whole week | L43: Score + 200-word weekly note + push | M43: 3 | N43: Math diagnostic v2
A44: 43 | B44: 46314 | C44: 7 | D44: Phase 2 - Classical & advanced ML | E44: Linear regression | F44: MSE, GD, normal equation, scaling | G44: NG C1 W1-2 | H44: NG | I44: https://www.coursera.org/specializations/machine-learning-introduction | J44: Linear regression from scratch vs sklearn | K44: Yesterday: Math diagnostic v2 | L44: `ml/linear.py` | M44: 3
A45: 44 | B45: 46315 | C45: 7 | D45: Phase 2 - Classical & advanced ML | E45: Logistic regression | F45: Sigmoid, log loss, boundary | G45: NG C1 W3 | H45: NG | I45: https://www.coursera.org/specializations/machine-learning-introduction | J45: Logistic from scratch | K45: Yesterday: Linear regression | L45: `ml/logistic.py` | M45: 3
A46: 45 | B46: 46316 | C46: 7 | D46: Phase 2 - Classical & advanced ML | E46: Regularisation & softmax | F46: L1/L2, early stopping, softmax regression | G46: NG C1 W3; GERON ch 4 | H46: GERON | I46: https://github.com/ageron/handson-ml3 | J46: Ridge/lasso paths; softmax on Iris | K46: Yesterday: Logistic regression | L46: Commit | M46: 3
A47: 46 | B47: 46317 | C47: 7 | D47: Phase 2 - Classical & advanced ML | E47: Classification metrics | F47: Confusion, P/R/F1, PR vs ROC, thresholds | G47: GERON ch 3 | H47: GERON | I47: https://github.com/ageron/handson-ml3 | J47: Metrics from scratch; curves | K47: Yesterday: Regularisation & softmax | L47: `ml/metrics.py` | M47: 3
A48: 47 | B48: 46318 | C48: 7 | D48: Phase 2 - Classical & advanced ML | E48: Calibration & cost | F48: Reliability diagrams, isotonic, expected cost | G48: GERON ch 3 + sklearn calibration docs | H48: GERON | I48: https://github.com/ageron/handson-ml3 | J48: Calibration curve; cost-based threshold | K48: Yesterday: Classification metrics | L48: Commit | M48: 3
A49: 48 | B49: 46319 | C49: 7 | D49: Phase 2 - Classical & advanced ML | E49: kNN & curse of dimensionality | F49: kNN; distances; link to ANN | G49: GERON ch 2 (kNN) + OWN | H49: OWN | I49: - | J49: kNN from scratch; dimensionality experiment | K49: Yesterday: Calibration & cost | L49: `ml/knn.py` + Anki | M49: 3
A50: 49 | B50: 46320 | C50: 7 | D50: Phase 2 - Classical & advanced ML | E50: WEEKLY CHECKPOINT 7: Regression, classification, metrics | F50: Whole week | G50: Anki + notes (30 min) | H50: OWN | I50: - | J50: Self-test 10 concept Qs + interview Qs: PR-AUC vs ROC-AUC; Why calibrate GBMs; kNN in high dimensions (score bands: <40 weak, 40-60 needs work, 60-75 acceptable, 75-90 strong, 90+ excellent; <75% => revise before next week) (60 min); redo hardest implementation from blank file (30 min) | K50: Whole week | L50: Score + 200-word weekly note + push | M50: 3
A51: 50 | B51: 46321 | C51: 8 | D51: Phase 2 - Classical & advanced ML | E51: Decision trees | F51: Entropy/Gini, CART, pruning | G51: GERON ch 6; NG C2 W4 | H51: GERON | I51: https://github.com/ageron/handson-ml3 | J51: CART from scratch | K51: Yesterday: kNN & curse of dimensionality | L51: `ml/tree.py` | M51: 3
A52: 51 | B52: 46322 | C52: 8 | D52: Phase 2 - Classical & advanced ML | E52: Random forests | F52: Bootstrap, feature subsampling, OOB | G52: GERON ch 7 | H52: GERON | I52: https://github.com/ageron/handson-ml3 | J52: RF from your tree | K52: Yesterday: Decision trees | L52: Commit | M52: 3
A53: 52 | B53: 46323 | C53: 8 | D53: Phase 2 - Classical & advanced ML | E53: Gradient boosting | F53: Residual fitting, shrinkage, early stopping | G53: GERON ch 7; XGBoost paper sec 2 (arxiv 1603.02754) | H53: GERON | I53: https://github.com/ageron/handson-ml3 | J53: Own GBM (regression + logistic) | K53: Yesterday: Random forests | L53: `ml/gbm.py` | M53: 3
A54: 53 | B54: 46324 | C54: 8 | D54: Phase 2 - Classical & advanced ML | E54: LightGBM/CatBoost in practice | F54: Histogram, leaf-wise, ordered boosting; key params | G54: LGBM tuning page | H54: LGBM | I54: https://lightgbm.readthedocs.io/en/latest/Parameters-Tuning.html | J54: Tune 5 params on AI4I; compare libs | K54: Yesterday: Gradient boosting | L54: Table | M54: 3
A55: 54 | B55: 46325 | C55: 8 | D55: Phase 2 - Classical & advanced ML | E55: SHAP | F55: Shapley values, TreeSHAP, PDP | G55: SHAP intro | H55: SHAP | I55: https://shap.readthedocs.io/ | J55: SHAP on GBM | K55: Yesterday: LightGBM/CatBoost in practice | L55: Plots | M55: 3
... A84: 83 | B84: 46354 | C84: 12 | D84: Phase 2 - Classical & advanced ML | E84: P1 defence | F84: 9 project questions | G84: Project/build day - no new reading | H84: OWN | I84: - | J84: Answer in writing; 5-min recorded explanation | K84: Yesterday: P1 API stub | L84: CP1 self-grade | M84: 4
A85: 84 | B85: 46355 | C85: 12 | D85: Phase 2 - Classical & advanced ML | E85: WEEKLY CHECKPOINT 12: PROJECT 1 (week 2) | F85: Whole week | G85: Anki + notes (30 min) | H85: OWN | I85: - | J85: Self-test 10 concept Qs + interview Qs: What leaked and how found; What you'd change in V2; Cost-curve interpretation (score bands: <40 weak, 40-60 needs work, 60-75 acceptable, 75-90 strong, 90+ excellent; <75% => revise before next week) (60 min); redo hardest implementation from blank file (30 min) | K85: Whole week | L85: Score + 200-word weekly note + push | M85: 4 | N85: CP1
A86: 85 | B86: 46356 | C86: 13 | D86: Phase 3 - Deep learning & PyTorch | E86: micrograd I | F86: Derivatives, graph, forward | G86: KZ micrograd (first half) | H86: KZ | I86: https://karpathy.ai/zero-to-hero.html | J86: Value class + forward | K86: Yesterday: P1 defence | L86: Commit | M86: 4
A87: 86 | B87: 46357 | C87: 13 | D87: Phase 3 - Deep learning & PyTorch | E87: micrograd II | F87: Backward, topological sort, MLP, training loop | G87: KZ micrograd (second half) | H87: KZ | I87: https://karpathy.ai/zero-to-hero.html | J87: backward() + MLP; gradient check | K87: Yesterday: micrograd I | L87: Gradcheck <1e-5 | M87: 4
A88: 87 | B88: 46358 | C88: 13 | D88: Phase 3 - Deep learning & PyTorch | E88: makemore 1 | F88: Bigram, NLL, one-layer NN | G88: KZ makemore 1 | H88: KZ | I88: https://karpathy.ai/zero-to-hero.html | J88: Bigram LM (counts + NN) | K88: Yesterday: micrograd II | L88: Commit | M88: 4
A89: 88 | B89: 46359 | C89: 13 | D89: Phase 3 - Deep learning & PyTorch | E89: makemore 2 | F89: Embeddings, context, mini-batch, LR sweep | G89: KZ makemore 2 | H89: KZ | I89: https://karpathy.ai/zero-to-hero.html | J89: MLP LM; LR sweep plot | K89: Yesterday: makemore 1 | L89: Commit | M89: 4
...

Sheet Sources
A1: Key | B1: Resource | C1: URL | D1: What to study | E1: What to skip
A2: MML | B2: Mathematics for Machine Learning (Deisenroth, Faisal, Ong) - free PDF | C2: https://mml-book.github.io/ | D2: Ch 2-8, 10 | E2: Ch 9, 11, 12
A3: 3B1B-LA | B3: 3Blue1Brown - Essence of Linear Algebra | C3: https://www.3blue1brown.com/topics/linear-algebra | D3: All 16 episodes | E3: -
A4: 3B1B-CALC | B4: 3Blue1Brown - Essence of Calculus | C4: https://www.3blue1brown.com/topics/calculus | D4: Ep 1-4, 6 | E4: -
A5: BRUCE | B5: Practical Statistics for Data Scientists (Bruce & Bruce, O'Reilly) | C5: https://www.oreilly.com/library/view/practical-statistics-for/9781492072935/ | D5: Ch 1-3 | E5: Ch 4-7
A6: NG | B6: Andrew Ng - Machine Learning Specialization (Coursera, audit free) | C6: https://www.coursera.org/specializations/machine-learning-introduction | D6: C1-C3 lectures; implement labs in NumPy/PyTorch | E6: TensorFlow labs
A7: GERON | B7: Hands-On Machine Learning, 3rd ed. (Géron) | C7: https://github.com/ageron/handson-ml3 | D7: Ch 2-9 | E7: Ch 10+ (Keras)
A8: SHAP | B8: SHAP documentation | C8: https://shap.readthedocs.io/ | D8: Intro + TreeExplainer | E8: Everything else
A9: LGBM | B9: LightGBM parameters docs | C9: https://lightgbm.readthedocs.io/en/latest/Parameters-Tuning.html | D9: Tuning page | E9: -
A10: KAGGLE-FE | B10: Kaggle Learn - Feature Engineering | C10: https://www.kaggle.com/learn/feature-engineering | D10: All | E10: -
A11: OPTUNA | B11: Optuna docs | C11: https://optuna.readthedocs.io/ | D11: Tutorial | E11: -
A12: IMBL | B12: imbalanced-learn user guide | C12: https://imbalanced-learn.org/stable/user_guide.html | D12: Over/under-sampling caveats | E12: -
... A108: OUTLINES | B108: Outlines (structured generation) | C108: https://github.com/dottxt-ai/outlines | D108: README | E108: -
