Workbook

Sheet Summary
A1: Progress summary (auto-calculated from the 'Practice 250' sheet)
A3: Sub-topic | B3: Problems | C3: Easy | D3: Medium | E3: Hard | F3: Done | G3: % done
A4: 1. Arrays & Hashing | B4: =COUNTA('Practice 250'!D6:D23) -> 18 | C4: =COUNTIF('Practice 250'!E6:E23,"Easy") -> 4 | D4: =COUNTIF('Practice 250'!E6:E23,"Medium") -> 13 | E4: =COUNTIF('Practice 250'!E6:E23,"Hard") -> 1 | F4: =COUNTIF('Practice 250'!I6:I23,"Done") -> 13 | G4: =IF(B4=0,0,F4/B4) -> 0.72222222
A5: 2. Prefix Sum & Matrix | B5: =COUNTA('Practice 250'!D25:D34) -> 10 | C5: =COUNTIF('Practice 250'!E25:E34,"Easy") -> 3 | D5: =COUNTIF('Practice 250'!E25:E34,"Medium") -> 7 | E5: =COUNTIF('Practice 250'!E25:E34,"Hard") -> 0 | F5: =COUNTIF('Practice 250'!I25:I34,"Done") -> 1 | G5: =IF(B5=0,0,F5/B5) -> 0.1
A6: 3. Two Pointers | B6: =COUNTA('Practice 250'!D36:D45) -> 10 | C6: =COUNTIF('Practice 250'!E36:E45,"Easy") -> 3 | D6: =COUNTIF('Practice 250'!E36:E45,"Medium") -> 7 | E6: =COUNTIF('Practice 250'!E36:E45,"Hard") -> 0 | F6: =COUNTIF('Practice 250'!I36:I45,"Done") -> 0 | G6: =IF(B6=0,0,F6/B6) -> 0
A7: 4. Sliding Window | B7: =COUNTA('Practice 250'!D47:D58) -> 12 | C7: =COUNTIF('Practice 250'!E47:E58,"Easy") -> 1 | D7: =COUNTIF('Practice 250'!E47:E58,"Medium") -> 9 | E7: =COUNTIF('Practice 250'!E47:E58,"Hard") -> 2 | F7: =COUNTIF('Practice 250'!I47:I58,"Done") -> 0 | G7: =IF(B7=0,0,F7/B7) -> 0
A8: 5. Stack & Monotonic Stack | B8: =COUNTA('Practice 250'!D60:D71) -> 12 | C8: =COUNTIF('Practice 250'!E60:E71,"Easy") -> 0 | D8: =COUNTIF('Practice 250'!E60:E71,"Medium") -> 8 | E8: =COUNTIF('Practice 250'!E60:E71,"Hard") -> 4 | F8: =COUNTIF('Practice 250'!I60:I71,"Done") -> 0 | G8: =IF(B8=0,0,F8/B8) -> 0
A9: 6. Binary Search | B9: =COUNTA('Practice 250'!D73:D84) -> 12 | C9: =COUNTIF('Practice 250'!E73:E84,"Easy") -> 3 | D9: =COUNTIF('Practice 250'!E73:E84,"Medium") -> 6 | E9: =COUNTIF('Practice 250'!E73:E84,"Hard") -> 3 | F9: =COUNTIF('Practice 250'!I73:I84,"Done") -> 0 | G9: =IF(B9=0,0,F9/B9) -> 0
A10: 7. Linked List | B10: =COUNTA('Practice 250'!D86:D97) -> 12 | C10: =COUNTIF('Practice 250'!E86:E97,"Easy") -> 0 | D10: =COUNTIF('Practice 250'!E86:E97,"Medium") -> 10 | E10: =COUNTIF('Practice 250'!E86:E97,"Hard") -> 2 | F10: =COUNTIF('Practice 250'!I86:I97,"Done") -> 0 | G10: =IF(B10=0,0,F10/B10) -> 0
A11: 8. Strings & Pattern Matching | B11: =COUNTA('Practice 250'!D99:D110) -> 12 | C11: =COUNTIF('Practice 250'!E99:E110,"Easy") -> 5 | D11: =COUNTIF('Practice 250'!E99:E110,"Medium") -> 6 | E11: =COUNTIF('Practice 250'!E99:E110,"Hard") -> 1 | F11: =COUNTIF('Practice 250'!I99:I110,"Done") -> 0 | G11: =IF(B11=0,0,F11/B11) -> 0
A12: 9. Binary Trees | B12: =COUNTA('Practice 250'!D112:D125) -> 14 | C12: =COUNTIF('Practice 250'!E112:E125,"Easy") -> 1 | D12: =COUNTIF('Practice 250'!E112:E125,"Medium") -> 10 | E12: =COUNTIF('Practice 250'!E112:E125,"Hard") -> 3 | F12: =COUNTIF('Practice 250'!I112:I125,"Done") -> 0 | G12: =IF(B12=0,0,F12/B12) -> 0
A13: 10. Binary Search Trees | B13: =COUNTA('Practice 250'!D127:D134) -> 8 | C13: =COUNTIF('Practice 250'!E127:E134,"Easy") -> 1 | D13: =COUNTIF('Practice 250'!E127:E134,"Medium") -> 7 | E13: =COUNTIF('Practice 250'!E127:E134,"Hard") -> 0 | F13: =COUNTIF('Practice 250'!I127:I134,"Done") -> 0 | G13: =IF(B13=0,0,F13/B13) -> 0
A14: 11. Heap / Priority Queue | B14: =COUNTA('Practice 250'!D136:D147) -> 12 | C14: =COUNTIF('Practice 250'!E136:E147,"Easy") -> 0 | D14: =COUNTIF('Practice 250'!E136:E147,"Medium") -> 8 | E14: =COUNTIF('Practice 250'!E136:E147,"Hard") -> 4 | F14: =COUNTIF('Practice 250'!I136:I147,"Done") -> 0 | G14: =IF(B14=0,0,F14/B14) -> 0
A15: 12. Trie | B15: =COUNTA('Practice 250'!D149:D154) -> 6 | C15: =COUNTIF('Practice 250'!E149:E154,"Easy") -> 0 | D15: =COUNTIF('Practice 250'!E149:E154,"Medium") -> 5 | E15: =COUNTIF('Practice 250'!E149:E154,"Hard") -> 1 | F15: =COUNTIF('Practice 250'!I149:I154,"Done") -> 0 | G15: =IF(B15=0,0,F15/B15) -> 0
A16: 13. Backtracking | B16: =COUNTA('Practice 250'!D156:D165) -> 10 | C16: =COUNTIF('Practice 250'!E156:E165,"Easy") -> 0 | D16: =COUNTIF('Practice 250'!E156:E165,"Medium") -> 7 | E16: =COUNTIF('Practice 250'!E156:E165,"Hard") -> 3 | F16: =COUNTIF('Practice 250'!I156:I165,"Done") -> 0 | G16: =IF(B16=0,0,F16/B16) -> 0
A17: 14. Graphs: BFS & DFS | B17: =COUNTA('Practice 250'!D167:D180) -> 14 | C17: =COUNTIF('Practice 250'!E167:E180,"Easy") -> 1 | D17: =COUNTIF('Practice 250'!E167:E180,"Medium") -> 12 | E17: =COUNTIF('Practice 250'!E167:E180,"Hard") -> 1 | F17: =COUNTIF('Practice 250'!I167:I180,"Done") -> 0 | G17: =IF(B17=0,0,F17/B17) -> 0
A18: 15. Graphs: Topological Sort, Union-Find, Shortest Path | B18: =COUNTA('Practice 250'!D182:D195) -> 14 | C18: =COUNTIF('Practice 250'!E182:E195,"Easy") -> 0 | D18: =COUNTIF('Practice 250'!E182:E195,"Medium") -> 12 | E18: =COUNTIF('Practice 250'!E182:E195,"Hard") -> 2 | F18: =COUNTIF('Practice 250'!I182:I195,"Done") -> 0 | G18: =IF(B18=0,0,F18/B18) -> 0
A19: 16. 1D Dynamic Programming | B19: =COUNTA('Practice 250'!D197:D210) -> 14 | C19: =COUNTIF('Practice 250'!E197:E210,"Easy") -> 2 | D19: =COUNTIF('Practice 250'!E197:E210,"Medium") -> 10 | E19: =COUNTIF('Practice 250'!E197:E210,"Hard") -> 2 | F19: =COUNTIF('Practice 250'!I197:I210,"Done") -> 0 | G19: =IF(B19=0,0,F19/B19) -> 0
A20: 17. 2D / Grid & String DP | B20: =COUNTA('Practice 250'!D212:D223) -> 12 | C20: =COUNTIF('Practice 250'!E212:E223,"Easy") -> 0 | D20: =COUNTIF('Practice 250'!E212:E223,"Medium") -> 8 | E20: =COUNTIF('Practice 250'!E212:E223,"Hard") -> 4 | F20: =COUNTIF('Practice 250'!I212:I223,"Done") -> 0 | G20: =IF(B20=0,0,F20/B20) -> 0
A21: 18. Knapsack, Subsequence & Interval DP | B21: =COUNTA('Practice 250'!D225:D234) -> 10 | C21: =COUNTIF('Practice 250'!E225:E234,"Easy") -> 0 | D21: =COUNTIF('Practice 250'!E225:E234,"Medium") -> 6 | E21: =COUNTIF('Practice 250'!E225:E234,"Hard") -> 4 | F21: =COUNTIF('Practice 250'!I225:I234,"Done") -> 0 | G21: =IF(B21=0,0,F21/B21) -> 0
A22: 19. Greedy & Intervals | B22: =COUNTA('Practice 250'!D236:D247) -> 12 | C22: =COUNTIF('Practice 250'!E236:E247,"Easy") -> 3 | D22: =COUNTIF('Practice 250'!E236:E247,"Medium") -> 8 | E22: =COUNTIF('Practice 250'!E236:E247,"Hard") -> 1 | F22: =COUNTIF('Practice 250'!I236:I247,"Done") -> 0 | G22: =IF(B22=0,0,F22/B22) -> 0
A23: 20. Bit Manipulation | B23: =COUNTA('Practice 250'!D249:D256) -> 8 | C23: =COUNTIF('Practice 250'!E249:E256,"Easy") -> 3 | D23: =COUNTIF('Practice 250'!E249:E256,"Medium") -> 5 | E23: =COUNTIF('Practice 250'!E249:E256,"Hard") -> 0 | F23: =COUNTIF('Practice 250'!I249:I256,"Done") -> 0 | G23: =IF(B23=0,0,F23/B23) -> 0
A24: 21. Math & Number Theory | B24: =COUNTA('Practice 250'!D258:D265) -> 8 | C24: =COUNTIF('Practice 250'!E258:E265,"Easy") -> 1 | D24: =COUNTIF('Practice 250'!E258:E265,"Medium") -> 6 | E24: =COUNTIF('Practice 250'!E258:E265,"Hard") -> 1 | F24: =COUNTIF('Practice 250'!I258:I265,"Done") -> 0 | G24: =IF(B24=0,0,F24/B24) -> 0
A25: 22. Design (LLD-style) | B25: =COUNTA('Practice 250'!D267:D276) -> 10 | C25: =COUNTIF('Practice 250'!E267:E276,"Easy") -> 2 | D25: =COUNTIF('Practice 250'!E267:E276,"Medium") -> 6 | E25: =COUNTIF('Practice 250'!E267:E276,"Hard") -> 2 | F25: =COUNTIF('Practice 250'!I267:I276,"Done") -> 0 | G25: =IF(B25=0,0,F25/B25) -> 0
A26: TOTAL | B26: =SUM(B4:B25) -> 250 | C26: =SUM(C4:C25) -> 33 | D26: =SUM(D4:D25) -> 176 | E26: =SUM(E4:E25) -> 41 | F26: =SUM(F4:F25) -> 14 | G26: =IF(B26=0,0,F26/B26) -> 0.056
A28: Already solved (revision sheet) | B28: =COUNTA('Already Solved'!D5:D171) -> 154
A29: Grand total (solved + new) | B29: =B26+B28 -> 404
A31: Legend: yellow cells on the other sheets are yours to fill; everything else is pre-filled.
A32: Suggested pace: 3 problems/day = 250 in ~12 weeks; 5/day = ~7 weeks. Do Easy first inside each topic, then Medium, then Hard.
A33: Revision rule: any problem marked 'Revise' should be re-attempted after 3 days and again after 2 weeks.
A34: Interview-critical sub-topics for product MNCs: Arrays/Hashing, Sliding Window, Stack, Binary Search, Trees, Graphs, 1D+2D DP, Design.
A35: Companies column is indicative (based on public LeetCode company tags and interview reports), not a guarantee for any specific drive.

Sheet Practice 250
A1: LeetCode Practice Set - 250 new problems grouped by sub-topic (MNC interview focus)
A2: How to use: work top-to-bottom inside each sub-topic (ordered easy -> hard). Fill only the yellow cells: Status (Done / Revise / Skipped), Date, Attempts, Notes. Companies are indicative tags from LeetCode/interview reports, not guarantees. This list excludes every problem on the 'Already Solved' sheet.
A4: # | B4: Sub-topic | C4: LC # | D4: Problem | E4: Difficulty | F4: Pattern / Key idea | G4: Companies (indicative) | H4: Link | I4: Status | J4: Date solved | K4: Attempts | L4: Notes
A5: 1. Arrays & Hashing (18 problems)
A6: 1 | B6: Arrays & Hashing | C6: 217 | D6: Contains Duplicate | E6: Easy | F6: Hash set | G6: Amazon, Microsoft, Adobe | H6: =HYPERLINK("https://leetcode.com/problems/contains-duplicate/","Open") -> Open | I6: Done | J6: 2026-09-05 | K6: 1 | L6: Example row - overwrite with your own entry
A7: 2 | B7: Arrays & Hashing | C7: 219 | D7: Contains Duplicate II | E7: Easy | F7: Hash map + window of k | G7: Amazon, Google | H7: =HYPERLINK("https://leetcode.com/problems/contains-duplicate-ii/","Open") -> Open | I7: done
A8: 3 | B8: Arrays & Hashing | C8: 169 | D8: Majority Element | E8: Easy | F8: Boyer-Moore voting | G8: Amazon, Microsoft, Zoho | H8: =HYPERLINK("https://leetcode.com/problems/majority-element/","Open") -> Open | I8: Done
A9: 4 | B9: Arrays & Hashing | C9: 229 | D9: Majority Element II | E9: Medium | F9: Boyer-Moore (2 candidates) | G9: Google, Amazon | H9: =HYPERLINK("https://leetcode.com/problems/majority-element-ii/","Open") -> Open | I9: Done
A10: 5 | B10: Arrays & Hashing | C10: 448 | D10: Find All Numbers Disappeared in an Array | E10: Easy | F10: Index-as-hash (mark negatives) | G10: Amazon, Microsoft | H10: =HYPERLINK("https://leetcode.com/problems/find-all-numbers-disappeared-in-an-array/","Open") -> Open | I10: Done
A11: 6 | B11: Arrays & Hashing | C11: 442 | D11: Find All Duplicates in an Array | E11: Medium | F11: Index-as-hash | G11: Amazon, Goldman Sachs | H11: =HYPERLINK("https://leetcode.com/problems/find-all-duplicates-in-an-array/","Open") -> Open | I11: Done
A12: 7 | B12: Arrays & Hashing | C12: 287 | D12: Find the Duplicate Number | E12: Medium | F12: Floyd cycle detection on array | G12: Amazon, Microsoft, Google | H12: =HYPERLINK("https://leetcode.com/problems/find-the-duplicate-number/","Open") -> Open | I12: Done
A13: 8 | B13: Arrays & Hashing | C13: 41 | D13: First Missing Positive | E13: Hard | F13: Cyclic sort / index marking | G13: Amazon, Microsoft, Uber | H13: =HYPERLINK("https://leetcode.com/problems/first-missing-positive/","Open") -> Open | I13: Done
A14: 9 | B14: Arrays & Hashing | C14: 238 | D14: Product of Array Except Self | E14: Medium | F14: Prefix & suffix products | G14: Amazon, Microsoft, Meta, Visa | H14: =HYPERLINK("https://leetcode.com/problems/product-of-array-except-self/","Open") -> Open
A15: 10 | B15: Arrays & Hashing | C15: 128 | D15: Longest Consecutive Sequence | E15: Medium | F15: Hash set, start-of-run check | G15: Amazon, Google, Goldman Sachs | H15: =HYPERLINK("https://leetcode.com/problems/longest-consecutive-sequence/","Open") -> Open | I15: Done
A16: 11 | B16: Arrays & Hashing | C16: 560 | D16: Subarray Sum Equals K | E16: Medium | F16: Prefix sum + hash map | G16: Meta, Amazon, Google, Visa | H16: =HYPERLINK("https://leetcode.com/problems/subarray-sum-equals-k/","Open") -> Open | I16: Done
A17: 12 | B17: Arrays & Hashing | C17: 189 | D17: Rotate Array | E17: Medium | F17: Three reversals | G17: Microsoft, Amazon, Zoho | H17: =HYPERLINK("https://leetcode.com/problems/rotate-array/","Open") -> Open | I17: Done
A18: 13 | B18: Arrays & Hashing | C18: 75 | D18: Sort Colors | E18: Medium | F18: Dutch national flag | G18: Microsoft, Amazon, Adobe | H18: =HYPERLINK("https://leetcode.com/problems/sort-colors/","Open") -> Open | L18: do check it once very different approach
A19: 14 | B19: Arrays & Hashing | C19: 31 | D19: Next Permutation | E19: Medium | F19: Pivot + swap + reverse | G19: Google, Microsoft, Amazon | H19: =HYPERLINK("https://leetcode.com/problems/next-permutation/","Open") -> Open
A20: 15 | B20: Arrays & Hashing | C20: 73 | D20: Set Matrix Zeroes | E20: Medium | F20: First row/col as markers | G20: Amazon, Microsoft, Oracle | H20: =HYPERLINK("https://leetcode.com/problems/set-matrix-zeroes/","Open") -> Open | I20: Done
A21: 16 | B21: Arrays & Hashing | C21: 48 | D21: Rotate Image | E21: Medium | F21: Transpose + reverse rows | G21: Microsoft, Amazon, Apple | H21: =HYPERLINK("https://leetcode.com/problems/rotate-image/","Open") -> Open
A22: 17 | B22: Arrays & Hashing | C22: 54 | D22: Spiral Matrix | E22: Medium | F22: Boundary shrinking | G22: Microsoft, Amazon, Zoho | H22: =HYPERLINK("https://leetcode.com/problems/spiral-matrix/","Open") -> Open | I22: Done
A23: 18 | B23: Arrays & Hashing | C23: 36 | D23: Valid Sudoku | E23: Medium | F23: Hash sets per row/col/box | G23: Amazon, Apple, Uber | H23: =HYPERLINK("https://leetcode.com/problems/valid-sudoku/","Open") -> Open
A24: 2. Prefix Sum & Matrix (10 problems)
A25: 19 | B25: Prefix Sum & Matrix | C25: 1480 | D25: Running Sum of 1d Array | E25: Easy | F25: Prefix sum | G25: Amazon, Adobe | H25: =HYPERLINK("https://leetcode.com/problems/running-sum-of-1d-array/","Open") -> Open | I25: Done
A26: 20 | B26: Prefix Sum & Matrix | C26: 724 | D26: Find Pivot Index | E26: Easy | F26: Prefix sum | G26: Amazon, Microsoft | H26: =HYPERLINK("https://leetcode.com/problems/find-pivot-index/","Open") -> Open
A27: 21 | B27: Prefix Sum & Matrix | C27: 303 | D27: Range Sum Query - Immutable | E27: Easy | F27: Prefix sum array | G27: Amazon, Goldman Sachs | H27: =HYPERLINK("https://leetcode.com/problems/range-sum-query-immutable/","Open") -> Open
A28: 22 | B28: Prefix Sum & Matrix | C28: 304 | D28: Range Sum Query 2D - Immutable | E28: Medium | F28: 2D prefix sum | G28: Google, Amazon, Meta | H28: =HYPERLINK("https://leetcode.com/problems/range-sum-query-2d-immutable/","Open") -> Open
A29: 23 | B29: Prefix Sum & Matrix | C29: 523 | D29: Continuous Subarray Sum | E29: Medium | F29: Prefix sum mod k + hash map | G29: Meta, Amazon | H29: =HYPERLINK("https://leetcode.com/problems/continuous-subarray-sum/","Open") -> Open
A30: 24 | B30: Prefix Sum & Matrix | C30: 974 | D30: Subarray Sums Divisible by K | E30: Medium | F30: Prefix mod counting | G30: Amazon, Goldman Sachs | H30: =HYPERLINK("https://leetcode.com/problems/subarray-sums-divisible-by-k/","Open") -> Open
A31: 25 | B31: Prefix Sum & Matrix | C31: 525 | D31: Contiguous Array | E31: Medium | F31: Prefix sum with +1/-1 | G31: Meta, Amazon | H31: =HYPERLINK("https://leetcode.com/problems/contiguous-array/","Open") -> Open
A32: 26 | B32: Prefix Sum & Matrix | C32: 1109 | D32: Corporate Flight Bookings | E32: Medium | F32: Difference array | G32: Amazon, Uber | H32: =HYPERLINK("https://leetcode.com/problems/corporate-flight-bookings/","Open") -> Open
A33: 27 | B33: Prefix Sum & Matrix | C33: 59 | D33: Spiral Matrix II | E33: Medium | F33: Boundary fill | G33: Microsoft, Amazon | H33: =HYPERLINK("https://leetcode.com/problems/spiral-matrix-ii/","Open") -> Open
A34: 28 | B34: Prefix Sum & Matrix | C34: 240 | D34: Search a 2D Matrix II | E34: Medium | F34: Staircase search from top-right | G34: Amazon, Microsoft, Adobe | H34: =HYPERLINK("https://leetcode.com/problems/search-a-2d-matrix-ii/","Open") -> Open
A35: 3. Two Pointers (10 problems)
A36: 29 | B36: Two Pointers | C36: 977 | D36: Squares of a Sorted Array | E36: Easy | F36: Two pointers from ends | G36: Amazon, Meta | H36: =HYPERLINK("https://leetcode.com/problems/squares-of-a-sorted-array/","Open") -> Open
A37: 30 | B37: Two Pointers | C37: 680 | D37: Valid Palindrome II | E37: Easy | F37: Skip one char, two pointers | G37: Meta, Amazon, Microsoft | H37: =HYPERLINK("https://leetcode.com/problems/valid-palindrome-ii/","Open") -> Open
A38: 31 | B38: Two Pointers | C38: 80 | D38: Remove Duplicates from Sorted Array II | E38: Medium | F38: Slow/fast pointers | G38: Microsoft, Amazon | H38: =HYPERLINK("https://leetcode.com/problems/remove-duplicates-from-sorted-array-ii/","Open") -> Open
A39: 32 | B39: Two Pointers | C39: 18 | D39: 4Sum | E39: Medium | F39: Sort + nested two pointers | G39: Amazon, Adobe, Goldman Sachs | H39: =HYPERLINK("https://leetcode.com/problems/4sum/","Open") -> Open
A40: 33 | B40: Two Pointers | C40: 16 | D40: 3Sum Closest | E40: Medium | F40: Sort + two pointers | G40: Amazon, Microsoft | H40: =HYPERLINK("https://leetcode.com/problems/3sum-closest/","Open") -> Open
A41: 34 | B41: Two Pointers | C41: 1679 | D41: Max Number of K-Sum Pairs | E41: Medium | F41: Sort + two pointers / hash map | G41: Amazon | H41: =HYPERLINK("https://leetcode.com/problems/max-number-of-k-sum-pairs/","Open") -> Open
...

Sheet Already Solved
A1: Problems you have already practiced - with LeetCode numbers
A2: Use this sheet for revision. Suggested: re-solve every Medium/Hard here once without looking at notes before interviews.
A4: # | B4: Sub-topic | C4: LC # | D4: Problem | E4: Difficulty | F4: Link | G4: Revised?
A5: Arrays (9)
A6: 1 | B6: Arrays | C6: 26 | D6: Remove Duplicates from Sorted Array | E6: Easy | F6: =HYPERLINK("https://leetcode.com/problems/remove-duplicates-from-sorted-array/","Open") -> Open
A7: 2 | B7: Arrays | C7: 27 | D7: Remove Element | E7: Easy | F7: =HYPERLINK("https://leetcode.com/problems/remove-element/","Open") -> Open
A8: 3 | B8: Arrays | C8: 344 | D8: Reverse String | E8: Easy | F8: =HYPERLINK("https://leetcode.com/problems/reverse-string/","Open") -> Open
A9: 4 | B9: Arrays | C9: 121 | D9: Best Time to Buy and Sell Stock | E9: Easy | F9: =HYPERLINK("https://leetcode.com/problems/best-time-to-buy-and-sell-stock/","Open") -> Open
A10: 5 | B10: Arrays | C10: 88 | D10: Merge Sorted Array | E10: Easy | F10: =HYPERLINK("https://leetcode.com/problems/merge-sorted-array/","Open") -> Open
A11: 6 | B11: Arrays | C11: 283 | D11: Move Zeroes | E11: Easy | F11: =HYPERLINK("https://leetcode.com/problems/move-zeroes/","Open") -> Open
A12: 7 | B12: Arrays | C12: 485 | D12: Max Consecutive Ones | E12: Easy | F12: =HYPERLINK("https://leetcode.com/problems/max-consecutive-ones/","Open") -> Open
A13: 8 | B13: Arrays | C13: 268 | D13: Missing Number | E13: Easy | F13: =HYPERLINK("https://leetcode.com/problems/missing-number/","Open") -> Open
A14: 9 | B14: Arrays | C14: 136 | D14: Single Number | E14: Easy | F14: =HYPERLINK("https://leetcode.com/problems/single-number/","Open") -> Open
A15: Linked List (14)
A16: 10 | B16: Linked List | C16: 707 | D16: Design Linked List | E16: Medium | F16: =HYPERLINK("https://leetcode.com/problems/design-linked-list/","Open") -> Open
A17: 11 | B17: Linked List | C17: 876 | D17: Middle of the Linked List | E17: Easy | F17: =HYPERLINK("https://leetcode.com/problems/middle-of-the-linked-list/","Open") -> Open
A18: 12 | B18: Linked List | C18: 206 | D18: Reverse Linked List | E18: Easy | F18: =HYPERLINK("https://leetcode.com/problems/reverse-linked-list/","Open") -> Open
A19: 13 | B19: Linked List | C19: 141 | D19: Linked List Cycle | E19: Easy | F19: =HYPERLINK("https://leetcode.com/problems/linked-list-cycle/","Open") -> Open
A20: 14 | B20: Linked List | C20: 234 | D20: Palindrome Linked List | E20: Easy | F20: =HYPERLINK("https://leetcode.com/problems/palindrome-linked-list/","Open") -> Open
A21: 15 | B21: Linked List | C21: 160 | D21: Intersection of Two Linked Lists | E21: Easy | F21: =HYPERLINK("https://leetcode.com/problems/intersection-of-two-linked-lists/","Open") -> Open
A22: 16 | B22: Linked List | C22: 203 | D22: Remove Linked List Elements | E22: Easy | F22: =HYPERLINK("https://leetcode.com/problems/remove-linked-list-elements/","Open") -> Open
A23: 17 | B23: Linked List | C23: 19 | D23: Remove Nth Node From End of List | E23: Medium | F23: =HYPERLINK("https://leetcode.com/problems/remove-nth-node-from-end-of-list/","Open") -> Open
A24: 18 | B24: Linked List | C24: 83 | D24: Remove Duplicates from Sorted List | E24: Easy | F24: =HYPERLINK("https://leetcode.com/problems/remove-duplicates-from-sorted-list/","Open") -> Open
A25: 19 | B25: Linked List | C25: 328 | D25: Odd Even Linked List | E25: Medium | F25: =HYPERLINK("https://leetcode.com/problems/odd-even-linked-list/","Open") -> Open
A26: 20 | B26: Linked List | C26: 2 | D26: Add Two Numbers | E26: Medium | F26: =HYPERLINK("https://leetcode.com/problems/add-two-numbers/","Open") -> Open
A27: 21 | B27: Linked List | C27: 21 | D27: Merge Two Sorted Lists | E27: Easy | F27: =HYPERLINK("https://leetcode.com/problems/merge-two-sorted-lists/","Open") -> Open
A28: 22 | B28: Linked List | C28: 61 | D28: Rotate List | E28: Medium | F28: =HYPERLINK("https://leetcode.com/problems/rotate-list/","Open") -> Open
A29: 23 | B29: Linked List | C29: 24 | D29: Swap Nodes in Pairs | E29: Medium | F29: =HYPERLINK("https://leetcode.com/problems/swap-nodes-in-pairs/","Open") -> Open
A30: Strings (19)
A31: 24 | B31: Strings | C31: 58 | D31: Length of Last Word | E31: Easy | F31: =HYPERLINK("https://leetcode.com/problems/length-of-last-word/","Open") -> Open
A32: 25 | B32: Strings | C32: 2942 | D32: Find Words Containing Character | E32: Easy | F32: =HYPERLINK("https://leetcode.com/problems/find-words-containing-character/","Open") -> Open
A33: 26 | B33: Strings | C33: 771 | D33: Jewels and Stones | E33: Easy | F33: =HYPERLINK("https://leetcode.com/problems/jewels-and-stones/","Open") -> Open
A34: 27 | B34: Strings | C34: 3541 | D34: Find Most Frequent Vowel and Consonant | E34: Easy | F34: =HYPERLINK("https://leetcode.com/problems/find-most-frequent-vowel-and-consonant/","Open") -> Open
A35: 28 | B35: Strings | C35: 1221 | D35: Split a String in Balanced Strings | E35: Easy | F35: =HYPERLINK("https://leetcode.com/problems/split-a-string-in-balanced-strings/","Open") -> Open
A36: 29 | B36: Strings | C36: 541 | D36: Reverse String II | E36: Easy | F36: =HYPERLINK("https://leetcode.com/problems/reverse-string-ii/","Open") -> Open
A37: 30 | B37: Strings | C37: 125 | D37: Valid Palindrome | E37: Easy | F37: =HYPERLINK("https://leetcode.com/problems/valid-palindrome/","Open") -> Open
A38: 31 | B38: Strings | C38: 1903 | D38: Largest Odd Number in String | E38: Easy | F38: =HYPERLINK("https://leetcode.com/problems/largest-odd-number-in-string/","Open") -> Open
A39: 32 | B39: Strings | C39: 14 | D39: Longest Common Prefix | E39: Easy | F39: =HYPERLINK("https://leetcode.com/problems/longest-common-prefix/","Open") -> Open
A40: 33 | B40: Strings | C40: 242 | D40: Valid Anagram | E40: Easy | F40: =HYPERLINK("https://leetcode.com/problems/valid-anagram/","Open") -> Open
A41: 34 | B41: Strings | C41: 205 | D41: Isomorphic Strings | E41: Easy | F41: =HYPERLINK("https://leetcode.com/problems/isomorphic-strings/","Open") -> Open
...
